Workbook

Sheet FC inventory
A1: Date | B1: Name of FC | C1: Movement | D1: Agemawo 1kg | E1: Boneless Beef 1kg | F1: Cow Hump 1kg | G1: Cow Head & Neck 1kg | H1: Goat Meat 1kg | I1: Chicken 1kg | J1: Titus 1kg (uncleaned) | K1: Titus 1kg (Cleaned) | L1: Hake 1kg (Cleaned) | M1: Hake 1kg (Uncleaned) | N1: Value Pack (Cow Tongue) | O1: Value Pack (Cow Assorted) | P1: Token Pack (Cow Minced Meat) | Q1: Token Pack (Agemawo) | R1: Token pack(boneless beef) | S1: Token Pack (Cow Tail) | T1: Token Pack (Cow Head & Neck) | U1: Token Pack (Cow Hump) | V1: Token Pack (Goat Meat) | W1: Token Pack (Chicken) | X1: Token Pack (Chicken Gizzard) | Y1: Token Pack (Pomo) | Z1: Token Pack (Shaki & Roundabout) | AA1: Token Pack (Cow Assorted) | AB1: Token Pack (Cow Leg) | AC1: Token Pack (Goat Assorted) | AD1: Token Pack (Titus) | AE1: Token Pack (Hake) | AF1: Token (small snail) | AG1: Token (big snail) | AH1: Token (Goat head & leg)
A2: 45317 | B2: BCT | C2: In | D2: 13 | E2: 5 | F2: 2 | G2: 3 | H2: 2 | I2: 60 | N2: 1 | O2: 2 | Q2: 17 | R2: 10 | S2: 2 | W2: 20 | X2: 5 | AA2: 6 | AB2: 5 | AC2: 1
A3: 45317 | B3: Bashorun | C3: In | D3: 13 | E3: 5 | G3: 3 | H3: 2 | I3: 60 | O3: 3 | R3: 10 | S3: 2 | W3: 17 | AA3: 6 | AB3: 5 | AC3: 1
A4: 45317 | B4: Apata | C4: In | D4: 13 | E4: 4 | F4: 1 | G4: 3 | H4: 1 | I4: 60 | N4: 1 | O4: 2 | Q4: 17 | R4: 10 | S4: 2 | W4: 20 | X4: 5 | AA4: 6 | AB4: 4 | AC4: 1
A5: 45317 | B5: BCT | C5: Out | D5: 4 | W5: 2
A6: 45318 | B6: Bashorun | C6: In | Q6: 17 | W6: 3 | X6: 5
A7: 45318 | B7: Felele | C7: In | D7: 11 | E7: 4 | F7: 2 | G7: 3 | H7: 2 | I7: 45 | N7: 1 | O7: 2 | Q7: 17 | R7: 10 | S7: 2 | W7: 20 | X7: 5 | AA7: 6 | AB7: 5 | AC7: 1
A8: 45318 | B8: Apata | C8: Out | D8: 1 | I8: 2 | R8: 1 | AA8: 1 | AB8: 1
A9: 45318 | B9: BCT | C9: Out | D9: 3 | E9: 1 | I9: 1 | O9: 1 | Q9: 2 | R9: 1 | S9: 1 | W9: 1 | X9: 1 | AA9: 2 | AB9: 1
A10: 45318 | B10: Bashorun | C10: Out | D10: 3 | I10: 3 | O10: 3 | R10: 1 | S10: 1 | W10: 3 | AA10: 1 | AB10: 1
A11: 45320 | B11: Alakia | C11: In | D11: 10 | E11: 4 | F11: 1 | G11: 1 | I11: 35 | N11: 1 | O11: 2 | Q11: 15 | R11: 8 | S11: 2 | W11: 14 | X11: 4 | AA11: 5 | AB11: 4 | AC11: 1
A12: 45320 | B12: Apata | C12: Out | D12: 1
A13: 45320 | B13: Bashorun | C13: Out | Q13: 1 | R13: 1 | S13: 1 | W13: 1 | X13: 3 | AC13: 1
A14: 45320 | B14: Alakia | C14: Out | I14: 1 | AA14: 1
A15: 45321 | B15: Alakia | C15: Out | F15: 1 | Q15: 1 | W15: 1 | AB15: 1
A16: 45321 | B16: Bashorun | C16: Out | I16: 2 | Q16: 1 | W16: 1
A17: 45321 | B17: Apata | C17: Out | E17: 1 | Q17: 2 | AB17: 3
A18: 45321 | B18: BCT | C18: Out | D18: 3 | AA18: 1
A19: 45321 | B19: Felele | C19: Out | D19: 1 | I19: 1 | Q19: 1 | S19: 2 | X19: 3 | AA19: 1
A20: 45322 | B20: Bashorun | C20: In | F20: 2
A21: 45322 | B21: Alakia | C21: Out | D21: 2 | I21: 3 | R21: 1 | X21: 1 | AA21: 1
A22: 45322 | B22: Bashorun | C22: Out | D22: 4 | E22: 1 | H22: 2 | I22: 1 | Q22: 1 | R22: 1 | W22: 1 | X22: 2 | AA22: 2 | AB22: 2
A23: 45322 | B23: Apata | C23: Out | D23: 2 | E23: 1 | Q23: 2 | R23: 1
A24: 45322 | B24: BCT | C24: Out | I24: 1 | Q24: 1
A25: 45322 | B25: Felele | C25: Out | D25: 2 | I25: 1
A26: 45323 | B26: Alakia | C26: Out | D26: 1 | G26: 1 | N26: 1 | S26: 1 | AB26: 1
A27: 45323 | B27: Bashorun | C27: Out | D27: 2 | I27: 3 | Q27: 1
A28: 45323 | B28: Apata | C28: Out | D28: 1
A29: 45323 | B29: BCT | C29: Out | D29: 1 | F29: 1 | I29: 1 | O29: 3 | X29: 1 | AA29: 1
A30: 45323 | B30: Felele | C30: Out | G30: 1 | I30: 5
A31: 45323 | B31: BCT | C31: In | O31: 2
A32: 45324 | B32: Alakia | C32: Out | I32: 1
A33: 45324 | B33: Bashorun | C33: Out | D33: 1 | I33: 2 | W33: 2 | AA33: 2
A34: 45324 | B34: Apata | C34: Out | X34: 2
A35: 45324 | B35: BCT | C35: Out | D35: 2 | G35: 2 | I35: 4 | Q35: 1 | X35: 2 | AA35: 1
A36: 45324 | B36: Felele | C36: Out | D36: 3 | F36: 1 | G36: 2 | O36: 1 | AB36: 1
A37: 45325 | B37: BCT | C37: In | D37: 7 | O37: 3 | X37: 4
A38: 45325 | B38: Bashorun | C38: In | D38: 7 | F38: 1 | I38: 5 | Q38: 10 | R38: 5 | W38: 8 | X38: 3 | AA38: 3 | AB38: 2
A39: 45325 | B39: Alakia | C39: Out | D39: 3 | Q39: 2 | S39: 1 | AA39: 2
A40: 45325 | B40: Bashorun | C40: Out | D40: 1 | I40: 2 | Q40: 4 | W40: 1
...

Sheet Apata
A1: =TODAY() -> 45889 | B1: Agemawo 1kg | C1: Boneless Beef 1kg | D1: Cow Hump 1kg | E1: Cow Head & Neck 1kg | F1: Goat Meat 1kg | G1: Chicken 1kg | H1: Titus 1kg (uncleaned) | I1: Titus 1kg (Cleaned) | J1: Hake 1kg (Cleaned) | K1: Hake 1kg (Uncleaned) | L1: Value Pack (Cow Tongue) | M1: Value Pack (Cow Assorted) | N1: Token Pack (Cow Minced Meat) | O1: Token Pack (Agemawo) | P1: Token pack(boneless beef) | Q1: Token Pack (Cow Tail) | R1: Token Pack (Cow Head & Neck) | S1: Token Pack (Cow Hump) | T1: Token Pack (Goat Meat) | U1: Token Pack (Chicken) | V1: Token Pack (Chicken Gizzard) | W1: Token Pack (Pomo) | X1: Token Pack (Shaki & Roundabout) | Y1: Token Pack (Cow Assorted) | Z1: Token Pack (Cow Leg) | AA1: Token Pack (Goat Assorted) | AB1: Token Pack (Titus) | AC1: Token Pack (Hake) | AD1: Token (small snail) | AE1: Token (big snail) | AF1: Token (Goat head & leg)
A2: Stock Count | B2: 0 | C2: 0 | D2: 0 | E2: 0 | F2: 0 | G2: 0 | H2: 0 | I2: 0 | J2: 0 | K2: 0 | L2: 0 | M2: 0 | N2: 0 | O2: 0 | P2: 0 | Q2: 0 | R2: 0 | S2: 0 | T2: 0 | U2: 0 | V2: 0 | W2: 0 | X2: 0 | Y2: 0 | Z2: 0 | AA2: 0 | AB2: 0 | AC2: 0 | AD2: 0 | AE2: 0 | AF2: 0
A3: Opening Stock | B3: =sumifs('FC inventory'!D2:D999,'FC inventory'!$A$2:$A999,"<"&$A$1,'FC inventory'!$B$2:$B999,"Apata",'FC inventory'!$C$2:$C999,"In")-sumifs('FC inventory'!D2:D999,'FC inventory'!$A$2:$A999,"<"&$A$1,'FC inventory'!$B$2:$B999,"Apata",'FC inventory'!$C$2:$C999,"Out")+SUMIFS('FC inventory'!D2:D999,'FC inventory'!$A$2:$A999,"<"&$A$1,'FC inventory'!$B$2:$B999,"Apata",'FC inventory'!$C$2:$C999,"Returned") -> 6 | C3: =sumifs('FC inventory'!E2:E999,'FC inventory'!$A$2:$A999,"<"&$A$1,'FC inventory'!$B$2:$B999,"Apata",'FC inventory'!$C$2:$C999,"In")-sumifs('FC inventory'!E2:E999,'FC inventory'!$A$2:$A999,"<"&$A$1,'FC inventory'!$B$2:$B999,"Apata",'FC inventory'!$C$2:$C999,"Out")+SUMIFS('FC inventory'!E2:E999,'FC inventory'!$A$2:$A999,"<"&$A$1,'FC inventory'!$B$2:$B999,"Apata",'FC inventory'!$C$2:$C999,"Returned") -> 0 | D3: =sumifs('FC inventory'!F2:F999,'FC inventory'!$A$2:$A999,"<"&$A$1,'FC inventory'!$B$2:$B999,"Apata",'FC inventory'!$C$2:$C999,"In")-sumifs('FC inventory'!F2:F999,'FC inventory'!$A$2:$A999,"<"&$A$1,'FC inventory'!$B$2:$B999,"Apata",'FC inventory'!$C$2:$C999,"Out")+SUMIFS('FC inventory'!F2:F999,'FC inventory'!$A$2:$A999,"<"&$A$1,'FC inventory'!$B$2:$B999,"Apata",'FC inventory'!$C$2:$C999,"Returned") -> 1 | E3: =sumifs('FC inventory'!G2:G999,'FC inventory'!$A$2:$A999,"<"&$A$1,'FC inventory'!$B$2:$B999,"Apata",'FC inventory'!$C$2:$C999,"In")-sumifs('FC inventory'!G2:G999,'FC inventory'!$A$2:$A999,"<"&$A$1,'FC inventory'!$B$2:$B999,"Apata",'FC inventory'!$C$2:$C999,"Out")+SUMIFS('FC inventory'!G2:G999,'FC inventory'!$A$2:$A999,"<"&$A$1,'FC inventory'!$B$2:$B999,"Apata",'FC inventory'!$C$2:$C999,"Returned") -> 3 | F3: =sumifs('FC inventory'!H2:H999,'FC inventory'!$A$2:$A999,"<"&$A$1,'FC inventory'!$B$2:$B999,"Apata",'FC inventory'!$C$2:$C999,"In")-sumifs('FC inventory'!H2:H999,'FC inventory'!$A$2:$A999,"<"&$A$1,'FC inventory'!$B$2:$B999,"Apata",'FC inventory'!$C$2:$C999,"Out")+SUMIFS('FC inventory'!H2:H999,'FC inventory'!$A$2:$A999,"<"&$A$1,'FC inventory'!$B$2:$B999,"Apata",'FC inventory'!$C$2:$C999,"Returned") -> 0 | G3: =sumifs('FC inventory'!I2:I999,'FC inventory'!$A$2:$A999,"<"&$A$1,'FC inventory'!$B$2:$B999,"Apata",'FC inventory'!$C$2:$C999,"In")-sumifs('FC inventory'!I2:I999,'FC inventory'!$A$2:$A999,"<"&$A$1,'FC inventory'!$B$2:$B999,"Apata",'FC inventory'!$C$2:$C999,"Out")+SUMIFS('FC inventory'!I2:I999,'FC inventory'!$A$2:$A999,"<"&$A$1,'FC inventory'!$B$2:$B999,"Apata",'FC inventory'!$C$2:$C999,"Returned") -> 56 | H3: =sumifs('FC inventory'!J2:J999,'FC inventory'!$A$2:$A999,"<"&$A$1,'FC inventory'!$B$2:$B999,"Apata",'FC inventory'!$C$2:$C999,"In")-sumifs('FC inventory'!J2:J999,'FC inventory'!$A$2:$A999,"<"&$A$1,'FC inventory'!$B$2:$B999,"Apata",'FC inventory'!$C$2:$C999,"Out")+SUMIFS('FC inventory'!J2:J999,'FC inventory'!$A$2:$A999,"<"&$A$1,'FC inventory'!$B$2:$B999,"Apata",'FC inventory'!$C$2:$C999,"Returned") -> 0 | I3: =sumifs('FC inventory'!K2:K999,'FC inventory'!$A$2:$A999,"<"&$A$1,'FC inventory'!$B$2:$B999,"Apata",'FC inventory'!$C$2:$C999,"In")-sumifs('FC inventory'!K2:K999,'FC inventory'!$A$2:$A999,"<"&$A$1,'FC inventory'!$B$2:$B999,"Apata",'FC inventory'!$C$2:$C999,"Out")+SUMIFS('FC inventory'!K2:K999,'FC inventory'!$A$2:$A999,"<"&$A$1,'FC inventory'!$B$2:$B999,"Apata",'FC inventory'!$C$2:$C999,"Returned") -> 0 | ... AF3: =sumifs('FC inventory'!AH2:AH999,'FC inventory'!$A$2:$A999,"<"&$A$1,'FC inventory'!$B$2:$B999,"Apata",'FC inventory'!$C$2:$C999,"In")-sumifs('FC inventory'!AH2:AH999,'FC inventory'!$A$2:$A999,"<"&$A$1,'FC inventory'!$B$2:$B999,"Apata",'FC inventory'!$C$2:$C999,"Out")+SUMIFS('FC inventory'!AH2:AH999,'FC inventory'!$A$2:$A999,"<"&$A$1,'FC inventory'!$B$2:$B999,"Apata",'FC inventory'!$C$2:$C999,"Returned") -> 0
A4: In | B4: =sumifs('FC inventory'!D2:D999,'FC inventory'!$A$2:$A999,$A$1,'FC inventory'!$B$2:$B999,"Apata",'FC inventory'!$C$2:$C999,"In") -> 0 | C4: =sumifs('FC inventory'!E2:E999,'FC inventory'!$A$2:$A999,$A$1,'FC inventory'!$B$2:$B999,"Apata",'FC inventory'!$C$2:$C999,"In") -> 0 | D4: =sumifs('FC inventory'!F2:F999,'FC inventory'!$A$2:$A999,$A$1,'FC inventory'!$B$2:$B999,"Apata",'FC inventory'!$C$2:$C999,"In") -> 0 | E4: =sumifs('FC inventory'!G2:G999,'FC inventory'!$A$2:$A999,$A$1,'FC inventory'!$B$2:$B999,"Apata",'FC inventory'!$C$2:$C999,"In") -> 0 | F4: =sumifs('FC inventory'!H2:H999,'FC inventory'!$A$2:$A999,$A$1,'FC inventory'!$B$2:$B999,"Apata",'FC inventory'!$C$2:$C999,"In") -> 0 | G4: =sumifs('FC inventory'!I2:I999,'FC inventory'!$A$2:$A999,$A$1,'FC inventory'!$B$2:$B999,"Apata",'FC inventory'!$C$2:$C999,"In") -> 0 | H4: =sumifs('FC inventory'!J2:J999,'FC inventory'!$A$2:$A999,$A$1,'FC inventory'!$B$2:$B999,"Apata",'FC inventory'!$C$2:$C999,"In") -> 0 | I4: =sumifs('FC inventory'!K2:K999,'FC inventory'!$A$2:$A999,$A$1,'FC inventory'!$B$2:$B999,"Apata",'FC inventory'!$C$2:$C999,"In") -> 0 | ... AF4: =sumifs('FC inventory'!AH2:AH999,'FC inventory'!$A$2:$A999,$A$1,'FC inventory'!$B$2:$B999,"Apata",'FC inventory'!$C$2:$C999,"In") -> 0
A5: Out | B5: =sumifs('FC inventory'!D2:D999,'FC inventory'!$A$2:$A999,$A$1,'FC inventory'!$B$2:$B999,"Apata",'FC inventory'!$C$2:$C999,"Out") -> 0 | C5: =sumifs('FC inventory'!E2:E999,'FC inventory'!$A$2:$A999,$A$1,'FC inventory'!$B$2:$B999,"Apata",'FC inventory'!$C$2:$C999,"Out") -> 0 | D5: =sumifs('FC inventory'!F2:F999,'FC inventory'!$A$2:$A999,$A$1,'FC inventory'!$B$2:$B999,"Apata",'FC inventory'!$C$2:$C999,"Out") -> 0 | E5: =sumifs('FC inventory'!G2:G999,'FC inventory'!$A$2:$A999,$A$1,'FC inventory'!$B$2:$B999,"Apata",'FC inventory'!$C$2:$C999,"Out") -> 0 | F5: =sumifs('FC inventory'!H2:H999,'FC inventory'!$A$2:$A999,$A$1,'FC inventory'!$B$2:$B999,"Apata",'FC inventory'!$C$2:$C999,"Out") -> 0 | G5: =sumifs('FC inventory'!I2:I999,'FC inventory'!$A$2:$A999,$A$1,'FC inventory'!$B$2:$B999,"Apata",'FC inventory'!$C$2:$C999,"Out") -> 0 | H5: =sumifs('FC inventory'!J2:J999,'FC inventory'!$A$2:$A999,$A$1,'FC inventory'!$B$2:$B999,"Apata",'FC inventory'!$C$2:$C999,"Out") -> 0 | I5: =sumifs('FC inventory'!K2:K999,'FC inventory'!$A$2:$A999,$A$1,'FC inventory'!$B$2:$B999,"Apata",'FC inventory'!$C$2:$C999,"Out") -> 0 | ... AF5: =sumifs('FC inventory'!AH2:AH999,'FC inventory'!$A$2:$A999,$A$1,'FC inventory'!$B$2:$B999,"Apata",'FC inventory'!$C$2:$C999,"Out") -> 0
A6: Returned | B6: =SUMIFS('FC inventory'!D2:D999,'FC inventory'!$A$2:$A999,$A$1,'FC inventory'!$B$2:$B999,"Apata",'FC inventory'!$C$2:$C999,"Returned") -> 0 | C6: =SUMIFS('FC inventory'!E2:E999,'FC inventory'!$A$2:$A999,$A$1,'FC inventory'!$B$2:$B999,"Apata",'FC inventory'!$C$2:$C999,"Returned") -> 0 | D6: =SUMIFS('FC inventory'!F2:F999,'FC inventory'!$A$2:$A999,$A$1,'FC inventory'!$B$2:$B999,"Apata",'FC inventory'!$C$2:$C999,"Returned") -> 0 | E6: =SUMIFS('FC inventory'!G2:G999,'FC inventory'!$A$2:$A999,$A$1,'FC inventory'!$B$2:$B999,"Apata",'FC inventory'!$C$2:$C999,"Returned") -> 0 | F6: =SUMIFS('FC inventory'!H2:H999,'FC inventory'!$A$2:$A999,$A$1,'FC inventory'!$B$2:$B999,"Apata",'FC inventory'!$C$2:$C999,"Returned") -> 0 | G6: =SUMIFS('FC inventory'!I2:I999,'FC inventory'!$A$2:$A999,$A$1,'FC inventory'!$B$2:$B999,"Apata",'FC inventory'!$C$2:$C999,"Returned") -> 0 | H6: =SUMIFS('FC inventory'!J2:J999,'FC inventory'!$A$2:$A999,$A$1,'FC inventory'!$B$2:$B999,"Apata",'FC inventory'!$C$2:$C999,"Returned") -> 0 | I6: =SUMIFS('FC inventory'!K2:K999,'FC inventory'!$A$2:$A999,$A$1,'FC inventory'!$B$2:$B999,"Apata",'FC inventory'!$C$2:$C999,"Returned") -> 0 | ... AF6: =SUMIFS('FC inventory'!AH2:AH999,'FC inventory'!$A$2:$A999,$A$1,'FC inventory'!$B$2:$B999,"Apata",'FC inventory'!$C$2:$C999,"Returned") -> 0
A7: Balance | B7: =B3+B4-B5+B6 -> 6 | C7: =C3+C4-C5+C6 -> 0 | D7: =D3+D4-D5+D6 -> 1 | E7: =E3+E4-E5+E6 -> 3 | F7: =F3+F4-F5+F6 -> 0 | G7: =G3+G4-G5+G6 -> 56 | H7: =H3+H4-H5+H6 -> 0 | I7: =I3+I4-I5+I6 -> 0 | ... AF7: =AF3+AF4-AF5+AF6 -> 0

Sheet Alakia
A1: =TODAY() -> 45889 | B1: Agemawo 1kg | C1: Boneless Beef 1kg | D1: Cow Hump 1kg | E1: Cow Head & Neck 1kg | F1: Goat Meat 1kg | G1: Chicken 1kg | H1: Titus 1kg (uncleaned) | I1: Titus 1kg (Cleaned) | J1: Hake 1kg (Cleaned) | K1: Hake 1kg (Uncleaned) | L1: Value Pack (Cow Tongue) | M1: Value Pack (Cow Assorted) | N1: Token Pack (Cow Minced Meat) | O1: Token Pack (Agemawo) | P1: Token pack(boneless beef) | Q1: Token Pack (Cow Tail) | R1: Token Pack (Cow Head & Neck) | S1: Token Pack (Cow Hump) | T1: Token Pack (Goat Meat) | U1: Token Pack (Chicken) | V1: Token Pack (Chicken Gizzard) | W1: Token Pack (Pomo) | X1: Token Pack (Shaki & Roundabout) | Y1: Token Pack (Cow Assorted) | Z1: Token Pack (Cow Leg) | AA1: Token Pack (Goat Assorted) | AB1: Token Pack (Titus) | AC1: Token Pack (Hake) | AD1: Token (small snail) | AE1: Token (big snail) | AF1: Token (Goat head & leg)
A2: Stock Count | B2: 0 | C2: 0 | D2: 0 | E2: 0 | F2: 0 | G2: 0 | H2: 0 | I2: 0 | J2: 0 | K2: 0 | L2: 0 | M2: 0 | N2: 0 | O2: 0 | P2: 0 | Q2: 0 | R2: 0 | S2: 0 | T2: 0 | U2: 0 | V2: 0 | W2: 0 | X2: 0 | Y2: 0 | Z2: 0 | AA2: 0 | AB2: 0 | AC2: 0 | AD2: 0 | AE2: 0 | AF2: 0
A3: Opening Stock | B3: =sumifs('FC inventory'!D2:D999,'FC inventory'!$A$2:$A999,"<"&$A$1,'FC inventory'!$B$2:$B999,"Alakia",'FC inventory'!$C$2:$C999,"In")-sumifs('FC inventory'!D2:D999,'FC inventory'!$A$2:$A999,"<"&$A$1,'FC inventory'!$B$2:$B999,"Alakia",'FC inventory'!$C$2:$C999,"Out")+SUMIFS('FC inventory'!D2:D999,'FC inventory'!$A$2:$A999,"<"&$A$1,'FC inventory'!$B$2:$B999,"Alakia",'FC inventory'!$C$2:$C999,"Returned") -> 0 | C3: =sumifs('FC inventory'!E2:E999,'FC inventory'!$A$2:$A999,"<"&$A$1,'FC inventory'!$B$2:$B999,"Alakia",'FC inventory'!$C$2:$C999,"In")-sumifs('FC inventory'!E2:E999,'FC inventory'!$A$2:$A999,"<"&$A$1,'FC inventory'!$B$2:$B999,"Alakia",'FC inventory'!$C$2:$C999,"Out")+SUMIFS('FC inventory'!E2:E999,'FC inventory'!$A$2:$A999,"<"&$A$1,'FC inventory'!$B$2:$B999,"Alakia",'FC inventory'!$C$2:$C999,"Returned") -> 3 | D3: =sumifs('FC inventory'!F2:F999,'FC inventory'!$A$2:$A999,"<"&$A$1,'FC inventory'!$B$2:$B999,"Alakia",'FC inventory'!$C$2:$C999,"In")-sumifs('FC inventory'!F2:F999,'FC inventory'!$A$2:$A999,"<"&$A$1,'FC inventory'!$B$2:$B999,"Alakia",'FC inventory'!$C$2:$C999,"Out")+SUMIFS('FC inventory'!F2:F999,'FC inventory'!$A$2:$A999,"<"&$A$1,'FC inventory'!$B$2:$B999,"Alakia",'FC inventory'!$C$2:$C999,"Returned") -> 0 | E3: =sumifs('FC inventory'!G2:G999,'FC inventory'!$A$2:$A999,"<"&$A$1,'FC inventory'!$B$2:$B999,"Alakia",'FC inventory'!$C$2:$C999,"In")-sumifs('FC inventory'!G2:G999,'FC inventory'!$A$2:$A999,"<"&$A$1,'FC inventory'!$B$2:$B999,"Alakia",'FC inventory'!$C$2:$C999,"Out")+SUMIFS('FC inventory'!G2:G999,'FC inventory'!$A$2:$A999,"<"&$A$1,'FC inventory'!$B$2:$B999,"Alakia",'FC inventory'!$C$2:$C999,"Returned") -> 0 | F3: =sumifs('FC inventory'!H2:H999,'FC inventory'!$A$2:$A999,"<"&$A$1,'FC inventory'!$B$2:$B999,"Alakia",'FC inventory'!$C$2:$C999,"In")-sumifs('FC inventory'!H2:H999,'FC inventory'!$A$2:$A999,"<"&$A$1,'FC inventory'!$B$2:$B999,"Alakia",'FC inventory'!$C$2:$C999,"Out")+SUMIFS('FC inventory'!H2:H999,'FC inventory'!$A$2:$A999,"<"&$A$1,'FC inventory'!$B$2:$B999,"Alakia",'FC inventory'!$C$2:$C999,"Returned") -> 0 | G3: =sumifs('FC inventory'!I2:I999,'FC inventory'!$A$2:$A999,"<"&$A$1,'FC inventory'!$B$2:$B999,"Alakia",'FC inventory'!$C$2:$C999,"In")-sumifs('FC inventory'!I2:I999,'FC inventory'!$A$2:$A999,"<"&$A$1,'FC inventory'!$B$2:$B999,"Alakia",'FC inventory'!$C$2:$C999,"Out")+SUMIFS('FC inventory'!I2:I999,'FC inventory'!$A$2:$A999,"<"&$A$1,'FC inventory'!$B$2:$B999,"Alakia",'FC inventory'!$C$2:$C999,"Returned") -> 25 | H3: =sumifs('FC inventory'!J2:J999,'FC inventory'!$A$2:$A999,"<"&$A$1,'FC inventory'!$B$2:$B999,"Alakia",'FC inventory'!$C$2:$C999,"In")-sumifs('FC inventory'!J2:J999,'FC inventory'!$A$2:$A999,"<"&$A$1,'FC inventory'!$B$2:$B999,"Alakia",'FC inventory'!$C$2:$C999,"Out")+SUMIFS('FC inventory'!J2:J999,'FC inventory'!$A$2:$A999,"<"&$A$1,'FC inventory'!$B$2:$B999,"Alakia",'FC inventory'!$C$2:$C999,"Returned") -> 0 | I3: =sumifs('FC inventory'!K2:K999,'FC inventory'!$A$2:$A999,"<"&$A$1,'FC inventory'!$B$2:$B999,"Alakia",'FC inventory'!$C$2:$C999,"In")-sumifs('FC inventory'!K2:K999,'FC inventory'!$A$2:$A999,"<"&$A$1,'FC inventory'!$B$2:$B999,"Alakia",'FC inventory'!$C$2:$C999,"Out")+SUMIFS('FC inventory'!K2:K999,'FC inventory'!$A$2:$A999,"<"&$A$1,'FC inventory'!$B$2:$B999,"Alakia",'FC inventory'!$C$2:$C999,"Returned") -> 0 | ... AF3: =sumifs('FC inventory'!AH2:AH999,'FC inventory'!$A$2:$A999,"<"&$A$1,'FC inventory'!$B$2:$B999,"Alakia",'FC inventory'!$C$2:$C999,"In")-sumifs('FC inventory'!AH2:AH999,'FC inventory'!$A$2:$A999,"<"&$A$1,'FC inventory'!$B$2:$B999,"Alakia",'FC inventory'!$C$2:$C999,"Out")+SUMIFS('FC inventory'!AH2:AH999,'FC inventory'!$A$2:$A999,"<"&$A$1,'FC inventory'!$B$2:$B999,"Alakia",'FC inventory'!$C$2:$C999,"Returned") -> 0
A4: In | B4: =sumifs('FC inventory'!D2:D999,'FC inventory'!$A$2:$A999,$A$1,'FC inventory'!$B$2:$B999,"Alakia",'FC inventory'!$C$2:$C999,"In") -> 0 | C4: =sumifs('FC inventory'!E2:E999,'FC inventory'!$A$2:$A999,$A$1,'FC inventory'!$B$2:$B999,"Alakia",'FC inventory'!$C$2:$C999,"In") -> 0 | D4: =sumifs('FC inventory'!F2:F999,'FC inventory'!$A$2:$A999,$A$1,'FC inventory'!$B$2:$B999,"Alakia",'FC inventory'!$C$2:$C999,"In") -> 0 | E4: =sumifs('FC inventory'!G2:G999,'FC inventory'!$A$2:$A999,$A$1,'FC inventory'!$B$2:$B999,"Alakia",'FC inventory'!$C$2:$C999,"In") -> 0 | F4: =sumifs('FC inventory'!H2:H999,'FC inventory'!$A$2:$A999,$A$1,'FC inventory'!$B$2:$B999,"Alakia",'FC inventory'!$C$2:$C999,"In") -> 0 | G4: =sumifs('FC inventory'!I2:I999,'FC inventory'!$A$2:$A999,$A$1,'FC inventory'!$B$2:$B999,"Alakia",'FC inventory'!$C$2:$C999,"In") -> 0 | H4: =sumifs('FC inventory'!J2:J999,'FC inventory'!$A$2:$A999,$A$1,'FC inventory'!$B$2:$B999,"Alakia",'FC inventory'!$C$2:$C999,"In") -> 0 | I4: =sumifs('FC inventory'!K2:K999,'FC inventory'!$A$2:$A999,$A$1,'FC inventory'!$B$2:$B999,"Alakia",'FC inventory'!$C$2:$C999,"In") -> 0 | ... AF4: =sumifs('FC inventory'!AH2:AH999,'FC inventory'!$A$2:$A999,$A$1,'FC inventory'!$B$2:$B999,"Alakia",'FC inventory'!$C$2:$C999,"In") -> 0
A5: Out | B5: =sumifs('FC inventory'!D2:D999,'FC inventory'!$A$2:$A999,$A$1,'FC inventory'!$B$2:$B999,"Alakia",'FC inventory'!$C$2:$C999,"Out") -> 0 | C5: =sumifs('FC inventory'!E2:E999,'FC inventory'!$A$2:$A999,$A$1,'FC inventory'!$B$2:$B999,"Alakia",'FC inventory'!$C$2:$C999,"Out") -> 0 | D5: =sumifs('FC inventory'!F2:F999,'FC inventory'!$A$2:$A999,$A$1,'FC inventory'!$B$2:$B999,"Alakia",'FC inventory'!$C$2:$C999,"Out") -> 0 | E5: =sumifs('FC inventory'!G2:G999,'FC inventory'!$A$2:$A999,$A$1,'FC inventory'!$B$2:$B999,"Alakia",'FC inventory'!$C$2:$C999,"Out") -> 0 | F5: =sumifs('FC inventory'!H2:H999,'FC inventory'!$A$2:$A999,$A$1,'FC inventory'!$B$2:$B999,"Alakia",'FC inventory'!$C$2:$C999,"Out") -> 0 | G5: =sumifs('FC inventory'!I2:I999,'FC inventory'!$A$2:$A999,$A$1,'FC inventory'!$B$2:$B999,"Alakia",'FC inventory'!$C$2:$C999,"Out") -> 0 | H5: =sumifs('FC inventory'!J2:J999,'FC inventory'!$A$2:$A999,$A$1,'FC inventory'!$B$2:$B999,"Alakia",'FC inventory'!$C$2:$C999,"Out") -> 0 | I5: =sumifs('FC inventory'!K2:K999,'FC inventory'!$A$2:$A999,$A$1,'FC inventory'!$B$2:$B999,"Alakia",'FC inventory'!$C$2:$C999,"Out") -> 0 | ... AF5: =sumifs('FC inventory'!AH2:AH999,'FC inventory'!$A$2:$A999,$A$1,'FC inventory'!$B$2:$B999,"Alakia",'FC inventory'!$C$2:$C999,"Out") -> 0
A6: Returned | B6: =SUMIFS('FC inventory'!D2:D999,'FC inventory'!$A$2:$A999,$A$1,'FC inventory'!$B$2:$B999,"Alakia",'FC inventory'!$C$2:$C999,"Returned") -> 0 | C6: =SUMIFS('FC inventory'!E2:E999,'FC inventory'!$A$2:$A999,$A$1,'FC inventory'!$B$2:$B999,"Alakia",'FC inventory'!$C$2:$C999,"Returned") -> 0 | D6: =SUMIFS('FC inventory'!F2:F999,'FC inventory'!$A$2:$A999,$A$1,'FC inventory'!$B$2:$B999,"Alakia",'FC inventory'!$C$2:$C999,"Returned") -> 0 | E6: =SUMIFS('FC inventory'!G2:G999,'FC inventory'!$A$2:$A999,$A$1,'FC inventory'!$B$2:$B999,"Alakia",'FC inventory'!$C$2:$C999,"Returned") -> 0 | F6: =SUMIFS('FC inventory'!H2:H999,'FC inventory'!$A$2:$A999,$A$1,'FC inventory'!$B$2:$B999,"Alakia",'FC inventory'!$C$2:$C999,"Returned") -> 0 | G6: =SUMIFS('FC inventory'!I2:I999,'FC inventory'!$A$2:$A999,$A$1,'FC inventory'!$B$2:$B999,"Alakia",'FC inventory'!$C$2:$C999,"Returned") -> 0 | H6: =SUMIFS('FC inventory'!J2:J999,'FC inventory'!$A$2:$A999,$A$1,'FC inventory'!$B$2:$B999,"Alakia",'FC inventory'!$C$2:$C999,"Returned") -> 0 | I6: =SUMIFS('FC inventory'!K2:K999,'FC inventory'!$A$2:$A999,$A$1,'FC inventory'!$B$2:$B999,"Alakia",'FC inventory'!$C$2:$C999,"Returned") -> 0 | ... AF6: =SUMIFS('FC inventory'!AH2:AH999,'FC inventory'!$A$2:$A999,$A$1,'FC inventory'!$B$2:$B999,"Alakia",'FC inventory'!$C$2:$C999,"Returned") -> 0
A7: Balance | B7: =B3+B4-B5+B6 -> 0 | C7: =C3+C4-C5+C6 -> 3 | D7: =D3+D4-D5+D6 -> 0 | E7: =E3+E4-E5+E6 -> 0 | F7: =F3+F4-F5+F6 -> 0 | G7: =G3+G4-G5+G6 -> 25 | H7: =H3+H4-H5+H6 -> 0 | I7: =I3+I4-I5+I6 -> 0 | ... AF7: =AF3+AF4-AF5+AF6 -> 0
AA18: .

Sheet Bashorun
A1: =TODAY() -> 45889 | B1: Agemawo 1kg | C1: Boneless Beef 1kg | D1: Cow Hump 1kg | E1: Cow Head & Neck 1kg | F1: Goat Meat 1kg | G1: Chicken 1kg | H1: Titus 1kg (uncleaned) | I1: Titus 1kg (Cleaned) | J1: Hake 1kg (Cleaned) | K1: Hake 1kg (Uncleaned) | L1: Value Pack (Cow Tongue) | M1: Value Pack (Cow Assorted) | N1: Token Pack (Cow Minced Meat) | O1: Token Pack (Agemawo) | P1: Token pack(boneless beef) | Q1: Token Pack (Cow Tail) | R1: Token Pack (Cow Head & Neck) | S1: Token Pack (Cow Hump) | T1: Token Pack (Goat Meat) | U1: Token Pack (Chicken) | V1: Token Pack (Chicken Gizzard) | W1: Token Pack (Pomo) | X1: Token Pack (Shaki & Roundabout) | Y1: Token Pack (Cow Assorted) | Z1: Token Pack (Cow Leg) | AA1: Token Pack (Goat Assorted) | AB1: Token Pack (Titus) | AC1: Token Pack (Hake) | AD1: Token (small snail) | AE1: Token (big snail) | AF1: Token (Goat head & leg)
A2: Stock Count | B2: 0 | C2: 0 | D2: 0 | E2: 0 | F2: 0 | G2: 0 | H2: 0 | I2: 0 | J2: 0 | K2: 0 | L2: 0 | M2: 0 | N2: 0 | O2: 0 | P2: 0 | Q2: 0 | R2: 0 | S2: 0 | T2: 0 | U2: 0 | V2: 0 | W2: 0 | X2: 0 | Y2: 0 | Z2: 0 | AA2: 0 | AB2: 0 | AC2: 0 | AD2: 0 | AE2: 0 | AF2: 0
A3: Opening Stock | B3: =sumifs('FC inventory'!D2:D984,'FC inventory'!$A$2:$A984,"<"&$A$1,'FC inventory'!$B$2:$B984,"Bashorun",'FC inventory'!$C$2:$C984,"In")-sumifs('FC inventory'!D2:D984,'FC inventory'!$A$2:$A984,"<"&$A$1,'FC inventory'!$B$2:$B984,"Bashorun",'FC inventory'!$C$2:$C984,"Out")+SUMIFS('FC inventory'!D2:D984,'FC inventory'!$A$2:$A984,"<"&$A$1,'FC inventory'!$B$2:$B984,"Bashorun",'FC inventory'!$C$2:$C984,"Returned") -> 0 | C3: =sumifs('FC inventory'!E2:E984,'FC inventory'!$A$2:$A984,"<"&$A$1,'FC inventory'!$B$2:$B984,"Bashorun",'FC inventory'!$C$2:$C984,"In")-sumifs('FC inventory'!E2:E984,'FC inventory'!$A$2:$A984,"<"&$A$1,'FC inventory'!$B$2:$B984,"Bashorun",'FC inventory'!$C$2:$C984,"Out")+SUMIFS('FC inventory'!E2:E984,'FC inventory'!$A$2:$A984,"<"&$A$1,'FC inventory'!$B$2:$B984,"Bashorun",'FC inventory'!$C$2:$C984,"Returned") -> 0 | D3: =sumifs('FC inventory'!F2:F984,'FC inventory'!$A$2:$A984,"<"&$A$1,'FC inventory'!$B$2:$B984,"Bashorun",'FC inventory'!$C$2:$C984,"In")-sumifs('FC inventory'!F2:F984,'FC inventory'!$A$2:$A984,"<"&$A$1,'FC inventory'!$B$2:$B984,"Bashorun",'FC inventory'!$C$2:$C984,"Out")+SUMIFS('FC inventory'!F2:F984,'FC inventory'!$A$2:$A984,"<"&$A$1,'FC inventory'!$B$2:$B984,"Bashorun",'FC inventory'!$C$2:$C984,"Returned") -> 1 | E3: =sumifs('FC inventory'!G2:G984,'FC inventory'!$A$2:$A984,"<"&$A$1,'FC inventory'!$B$2:$B984,"Bashorun",'FC inventory'!$C$2:$C984,"In")-sumifs('FC inventory'!G2:G984,'FC inventory'!$A$2:$A984,"<"&$A$1,'FC inventory'!$B$2:$B984,"Bashorun",'FC inventory'!$C$2:$C984,"Out")+SUMIFS('FC inventory'!G2:G984,'FC inventory'!$A$2:$A984,"<"&$A$1,'FC inventory'!$B$2:$B984,"Bashorun",'FC inventory'!$C$2:$C984,"Returned") -> 0 | F3: =sumifs('FC inventory'!H2:H984,'FC inventory'!$A$2:$A984,"<"&$A$1,'FC inventory'!$B$2:$B984,"Bashorun",'FC inventory'!$C$2:$C984,"In")-sumifs('FC inventory'!H2:H984,'FC inventory'!$A$2:$A984,"<"&$A$1,'FC inventory'!$B$2:$B984,"Bashorun",'FC inventory'!$C$2:$C984,"Out")+SUMIFS('FC inventory'!H2:H984,'FC inventory'!$A$2:$A984,"<"&$A$1,'FC inventory'!$B$2:$B984,"Bashorun",'FC inventory'!$C$2:$C984,"Returned") -> 0 | G3: =sumifs('FC inventory'!I2:I984,'FC inventory'!$A$2:$A984,"<"&$A$1,'FC inventory'!$B$2:$B984,"Bashorun",'FC inventory'!$C$2:$C984,"In")-sumifs('FC inventory'!I2:I984,'FC inventory'!$A$2:$A984,"<"&$A$1,'FC inventory'!$B$2:$B984,"Bashorun",'FC inventory'!$C$2:$C984,"Out")+SUMIFS('FC inventory'!I2:I984,'FC inventory'!$A$2:$A984,"<"&$A$1,'FC inventory'!$B$2:$B984,"Bashorun",'FC inventory'!$C$2:$C984,"Returned") -> 42 | H3: =sumifs('FC inventory'!J2:J984,'FC inventory'!$A$2:$A984,"<"&$A$1,'FC inventory'!$B$2:$B984,"Bashorun",'FC inventory'!$C$2:$C984,"In")-sumifs('FC inventory'!J2:J984,'FC inventory'!$A$2:$A984,"<"&$A$1,'FC inventory'!$B$2:$B984,"Bashorun",'FC inventory'!$C$2:$C984,"Out")+SUMIFS('FC inventory'!J2:J984,'FC inventory'!$A$2:$A984,"<"&$A$1,'FC inventory'!$B$2:$B984,"Bashorun",'FC inventory'!$C$2:$C984,"Returned") -> 0 | I3: =sumifs('FC inventory'!K2:K984,'FC inventory'!$A$2:$A984,"<"&$A$1,'FC inventory'!$B$2:$B984,"Bashorun",'FC inventory'!$C$2:$C984,"In")-sumifs('FC inventory'!K2:K984,'FC inventory'!$A$2:$A984,"<"&$A$1,'FC inventory'!$B$2:$B984,"Bashorun",'FC inventory'!$C$2:$C984,"Out")+SUMIFS('FC inventory'!K2:K984,'FC inventory'!$A$2:$A984,"<"&$A$1,'FC inventory'!$B$2:$B984,"Bashorun",'FC inventory'!$C$2:$C984,"Returned") -> 0 | ... AF3: =sumifs('FC inventory'!AH2:AH984,'FC inventory'!$A$2:$A984,"<"&$A$1,'FC inventory'!$B$2:$B984,"Bashorun",'FC inventory'!$C$2:$C984,"In")-sumifs('FC inventory'!AH2:AH984,'FC inventory'!$A$2:$A984,"<"&$A$1,'FC inventory'!$B$2:$B984,"Bashorun",'FC inventory'!$C$2:$C984,"Out")+SUMIFS('FC inventory'!AH2:AH984,'FC inventory'!$A$2:$A984,"<"&$A$1,'FC inventory'!$B$2:$B984,"Bashorun",'FC inventory'!$C$2:$C984,"Returned") -> 0
A4: In | B4: =sumifs('FC inventory'!D2:D984,'FC inventory'!$A$2:$A984,$A$1,'FC inventory'!$B$2:$B984,"Bashorun",'FC inventory'!$C$2:$C984,"In") -> 0 | C4: =sumifs('FC inventory'!E2:E984,'FC inventory'!$A$2:$A984,$A$1,'FC inventory'!$B$2:$B984,"Bashorun",'FC inventory'!$C$2:$C984,"In") -> 0 | D4: =sumifs('FC inventory'!F2:F984,'FC inventory'!$A$2:$A984,$A$1,'FC inventory'!$B$2:$B984,"Bashorun",'FC inventory'!$C$2:$C984,"In") -> 0 | E4: =sumifs('FC inventory'!G2:G984,'FC inventory'!$A$2:$A984,$A$1,'FC inventory'!$B$2:$B984,"Bashorun",'FC inventory'!$C$2:$C984,"In") -> 0 | F4: =sumifs('FC inventory'!H2:H984,'FC inventory'!$A$2:$A984,$A$1,'FC inventory'!$B$2:$B984,"Bashorun",'FC inventory'!$C$2:$C984,"In") -> 0 | G4: =sumifs('FC inventory'!I2:I984,'FC inventory'!$A$2:$A984,$A$1,'FC inventory'!$B$2:$B984,"Bashorun",'FC inventory'!$C$2:$C984,"In") -> 0 | H4: =sumifs('FC inventory'!J2:J984,'FC inventory'!$A$2:$A984,$A$1,'FC inventory'!$B$2:$B984,"Bashorun",'FC inventory'!$C$2:$C984,"In") -> 0 | I4: =sumifs('FC inventory'!K2:K984,'FC inventory'!$A$2:$A984,$A$1,'FC inventory'!$B$2:$B984,"Bashorun",'FC inventory'!$C$2:$C984,"In") -> 0 | ... AF4: =sumifs('FC inventory'!AH2:AH984,'FC inventory'!$A$2:$A984,$A$1,'FC inventory'!$B$2:$B984,"Bashorun",'FC inventory'!$C$2:$C984,"In") -> 0
A5: Out | B5: =sumifs('FC inventory'!D2:D984,'FC inventory'!$A$2:$A984,$A$1,'FC inventory'!$B$2:$B984,"Bashorun",'FC inventory'!$C$2:$C984,"Out") -> 0 | C5: =sumifs('FC inventory'!E2:E984,'FC inventory'!$A$2:$A984,$A$1,'FC inventory'!$B$2:$B984,"Bashorun",'FC inventory'!$C$2:$C984,"Out") -> 0 | D5: =sumifs('FC inventory'!F2:F984,'FC inventory'!$A$2:$A984,$A$1,'FC inventory'!$B$2:$B984,"Bashorun",'FC inventory'!$C$2:$C984,"Out") -> 0 | E5: =sumifs('FC inventory'!G2:G984,'FC inventory'!$A$2:$A984,$A$1,'FC inventory'!$B$2:$B984,"Bashorun",'FC inventory'!$C$2:$C984,"Out") -> 0 | F5: =sumifs('FC inventory'!H2:H984,'FC inventory'!$A$2:$A984,$A$1,'FC inventory'!$B$2:$B984,"Bashorun",'FC inventory'!$C$2:$C984,"Out") -> 0 | G5: =sumifs('FC inventory'!I2:I984,'FC inventory'!$A$2:$A984,$A$1,'FC inventory'!$B$2:$B984,"Bashorun",'FC inventory'!$C$2:$C984,"Out") -> 0 | H5: =sumifs('FC inventory'!J2:J984,'FC inventory'!$A$2:$A984,$A$1,'FC inventory'!$B$2:$B984,"Bashorun",'FC inventory'!$C$2:$C984,"Out") -> 0 | I5: =sumifs('FC inventory'!K2:K984,'FC inventory'!$A$2:$A984,$A$1,'FC inventory'!$B$2:$B984,"Bashorun",'FC inventory'!$C$2:$C984,"Out") -> 0 | ... AF5: =sumifs('FC inventory'!AH2:AH984,'FC inventory'!$A$2:$A984,$A$1,'FC inventory'!$B$2:$B984,"Bashorun",'FC inventory'!$C$2:$C984,"Out") -> 0
A6: Returned | B6: =SUMIFS('FC inventory'!D2:D984,'FC inventory'!$A$2:$A984,$A$1,'FC inventory'!$B$2:$B984,"Bashorun",'FC inventory'!$C$2:$C984,"Returned") -> 0 | C6: =SUMIFS('FC inventory'!E2:E984,'FC inventory'!$A$2:$A984,$A$1,'FC inventory'!$B$2:$B984,"Bashorun",'FC inventory'!$C$2:$C984,"Returned") -> 0 | D6: =SUMIFS('FC inventory'!F2:F984,'FC inventory'!$A$2:$A984,$A$1,'FC inventory'!$B$2:$B984,"Bashorun",'FC inventory'!$C$2:$C984,"Returned") -> 0 | E6: =SUMIFS('FC inventory'!G2:G984,'FC inventory'!$A$2:$A984,$A$1,'FC inventory'!$B$2:$B984,"Bashorun",'FC inventory'!$C$2:$C984,"Returned") -> 0 | F6: =SUMIFS('FC inventory'!H2:H984,'FC inventory'!$A$2:$A984,$A$1,'FC inventory'!$B$2:$B984,"Bashorun",'FC inventory'!$C$2:$C984,"Returned") -> 0 | G6: =SUMIFS('FC inventory'!I2:I984,'FC inventory'!$A$2:$A984,$A$1,'FC inventory'!$B$2:$B984,"Bashorun",'FC inventory'!$C$2:$C984,"Returned") -> 0 | H6: =SUMIFS('FC inventory'!J2:J984,'FC inventory'!$A$2:$A984,$A$1,'FC inventory'!$B$2:$B984,"Bashorun",'FC inventory'!$C$2:$C984,"Returned") -> 0 | I6: =SUMIFS('FC inventory'!K2:K984,'FC inventory'!$A$2:$A984,$A$1,'FC inventory'!$B$2:$B984,"Bashorun",'FC inventory'!$C$2:$C984,"Returned") -> 0 | ... AF6: =SUMIFS('FC inventory'!AH2:AH984,'FC inventory'!$A$2:$A984,$A$1,'FC inventory'!$B$2:$B984,"Bashorun",'FC inventory'!$C$2:$C984,"Returned") -> 0
A7: Balance | B7: =B3+B4-B5+B6 -> 0 | C7: =C3+C4-C5+C6 -> 0 | D7: =D3+D4-D5+D6 -> 1 | E7: =E3+E4-E5+E6 -> 0 | F7: =F3+F4-F5+F6 -> 0 | G7: =G3+G4-G5+G6 -> 42 | H7: =H3+H4-H5+H6 -> 0 | I7: =I3+I4-I5+I6 -> 0 | ... AF7: =AF3+AF4-AF5+AF6 -> 0

Sheet BCT
A1: =TODAY() -> 45889 | B1: Agemawo 1kg | C1: Boneless Beef 1kg | D1: Cow Hump 1kg | E1: Cow Head & Neck 1kg | F1: Goat Meat 1kg | G1: Chicken 1kg | H1: Titus 1kg (uncleaned) | I1: Titus 1kg (Cleaned) | J1: Hake 1kg (Cleaned) | K1: Hake 1kg (Uncleaned) | L1: Value Pack (Cow Tongue) | M1: Value Pack (Cow Assorted) | N1: Token Pack (Cow Minced Meat) | O1: Token Pack (Agemawo) | P1: Token pack(boneless beef) | Q1: Token Pack (Cow Tail) | R1: Token Pack (Cow Head & Neck) | S1: Token Pack (Cow Hump) | T1: Token Pack (Goat Meat) | U1: Token Pack (Chicken) | V1: Token Pack (Chicken Gizzard) | W1: Token Pack (Pomo) | X1: Token Pack (Shaki & Roundabout) | Y1: Token Pack (Cow Assorted) | Z1: Token Pack (Cow Leg) | AA1: Token Pack (Goat Assorted) | AB1: Token Pack (Titus) | AC1: Token Pack (Hake) | AD1: Token (small snail) | AE1: Token (big snail) | AF1: Token (Goat head & leg)
A2: Stock Count | B2: 0 | C2: 0 | D2: 0 | E2: 0 | F2: 0 | G2: 0 | H2: 0 | I2: 0 | J2: 0 | K2: 0 | L2: 0 | M2: 0 | N2: 0 | O2: 0 | P2: 0 | Q2: 0 | R2: 0 | S2: 0 | T2: 0 | U2: 0 | V2: 0 | W2: 0 | X2: 0 | Y2: 0 | Z2: 0 | AA2: 0 | AB2: 0 | AC2: 0 | AD2: 0 | AE2: 0 | AF2: 0
A3: Opening Stock | B3: =sumifs('FC inventory'!D2:D999,'FC inventory'!$A$2:$A999,"<"&$A$1,'FC inventory'!$B$2:$B999,"BCT",'FC inventory'!$C$2:$C999,"In")-sumifs('FC inventory'!D2:D999,'FC inventory'!$A$2:$A999,"<"&$A$1,'FC inventory'!$B$2:$B999,"BCT",'FC inventory'!$C$2:$C999,"Out")+SUMIFS('FC inventory'!D2:D999,'FC inventory'!$A$2:$A999,"<"&$A$1,'FC inventory'!$B$2:$B999,"BCT",'FC inventory'!$C$2:$C999,"Returned") -> -2 | C3: =sumifs('FC inventory'!E2:E999,'FC inventory'!$A$2:$A999,"<"&$A$1,'FC inventory'!$B$2:$B999,"BCT",'FC inventory'!$C$2:$C999,"In")-sumifs('FC inventory'!E2:E999,'FC inventory'!$A$2:$A999,"<"&$A$1,'FC inventory'!$B$2:$B999,"BCT",'FC inventory'!$C$2:$C999,"Out")+SUMIFS('FC inventory'!E2:E999,'FC inventory'!$A$2:$A999,"<"&$A$1,'FC inventory'!$B$2:$B999,"BCT",'FC inventory'!$C$2:$C999,"Returned") -> 0 | D3: =sumifs('FC inventory'!F2:F999,'FC inventory'!$A$2:$A999,"<"&$A$1,'FC inventory'!$B$2:$B999,"BCT",'FC inventory'!$C$2:$C999,"In")-sumifs('FC inventory'!F2:F999,'FC inventory'!$A$2:$A999,"<"&$A$1,'FC inventory'!$B$2:$B999,"BCT",'FC inventory'!$C$2:$C999,"Out")+SUMIFS('FC inventory'!F2:F999,'FC inventory'!$A$2:$A999,"<"&$A$1,'FC inventory'!$B$2:$B999,"BCT",'FC inventory'!$C$2:$C999,"Returned") -> 0 | E3: =sumifs('FC inventory'!G2:G999,'FC inventory'!$A$2:$A999,"<"&$A$1,'FC inventory'!$B$2:$B999,"BCT",'FC inventory'!$C$2:$C999,"In")-sumifs('FC inventory'!G2:G999,'FC inventory'!$A$2:$A999,"<"&$A$1,'FC inventory'!$B$2:$B999,"BCT",'FC inventory'!$C$2:$C999,"Out")+SUMIFS('FC inventory'!G2:G999,'FC inventory'!$A$2:$A999,"<"&$A$1,'FC inventory'!$B$2:$B999,"BCT",'FC inventory'!$C$2:$C999,"Returned") -> -1 | F3: =sumifs('FC inventory'!H2:H999,'FC inventory'!$A$2:$A999,"<"&$A$1,'FC inventory'!$B$2:$B999,"BCT",'FC inventory'!$C$2:$C999,"In")-sumifs('FC inventory'!H2:H999,'FC inventory'!$A$2:$A999,"<"&$A$1,'FC inventory'!$B$2:$B999,"BCT",'FC inventory'!$C$2:$C999,"Out")+SUMIFS('FC inventory'!H2:H999,'FC inventory'!$A$2:$A999,"<"&$A$1,'FC inventory'!$B$2:$B999,"BCT",'FC inventory'!$C$2:$C999,"Returned") -> 0 | G3: =sumifs('FC inventory'!I2:I999,'FC inventory'!$A$2:$A999,"<"&$A$1,'FC inventory'!$B$2:$B999,"BCT",'FC inventory'!$C$2:$C999,"In")-sumifs('FC inventory'!I2:I999,'FC inventory'!$A$2:$A999,"<"&$A$1,'FC inventory'!$B$2:$B999,"BCT",'FC inventory'!$C$2:$C999,"Out")+SUMIFS('FC inventory'!I2:I999,'FC inventory'!$A$2:$A999,"<"&$A$1,'FC inventory'!$B$2:$B999,"BCT",'FC inventory'!$C$2:$C999,"Returned") -> 35 | H3: =sumifs('FC inventory'!J2:J999,'FC inventory'!$A$2:$A999,"<"&$A$1,'FC inventory'!$B$2:$B999,"BCT",'FC inventory'!$C$2:$C999,"In")-sumifs('FC inventory'!J2:J999,'FC inventory'!$A$2:$A999,"<"&$A$1,'FC inventory'!$B$2:$B999,"BCT",'FC inventory'!$C$2:$C999,"Out")+SUMIFS('FC inventory'!J2:J999,'FC inventory'!$A$2:$A999,"<"&$A$1,'FC inventory'!$B$2:$B999,"BCT",'FC inventory'!$C$2:$C999,"Returned") -> 0 | I3: =sumifs('FC inventory'!K2:K999,'FC inventory'!$A$2:$A999,"<"&$A$1,'FC inventory'!$B$2:$B999,"BCT",'FC inventory'!$C$2:$C999,"In")-sumifs('FC inventory'!K2:K999,'FC inventory'!$A$2:$A999,"<"&$A$1,'FC inventory'!$B$2:$B999,"BCT",'FC inventory'!$C$2:$C999,"Out")+SUMIFS('FC inventory'!K2:K999,'FC inventory'!$A$2:$A999,"<"&$A$1,'FC inventory'!$B$2:$B999,"BCT",'FC inventory'!$C$2:$C999,"Returned") -> 0 | ... AF3: =sumifs('FC inventory'!AH2:AH999,'FC inventory'!$A$2:$A999,"<"&$A$1,'FC inventory'!$B$2:$B999,"BCT",'FC inventory'!$C$2:$C999,"In")-sumifs('FC inventory'!AH2:AH999,'FC inventory'!$A$2:$A999,"<"&$A$1,'FC inventory'!$B$2:$B999,"BCT",'FC inventory'!$C$2:$C999,"Out")+SUMIFS('FC inventory'!AH2:AH999,'FC inventory'!$A$2:$A999,"<"&$A$1,'FC inventory'!$B$2:$B999,"BCT",'FC inventory'!$C$2:$C999,"Returned") -> 0
A4: In | B4: =sumifs('FC inventory'!D2:D999,'FC inventory'!$A$2:$A999,$A$1,'FC inventory'!$B$2:$B999,"BCT",'FC inventory'!$C$2:$C999,"In") -> 0 | C4: =sumifs('FC inventory'!E2:E999,'FC inventory'!$A$2:$A999,$A$1,'FC inventory'!$B$2:$B999,"BCT",'FC inventory'!$C$2:$C999,"In") -> 0 | D4: =sumifs('FC inventory'!F2:F999,'FC inventory'!$A$2:$A999,$A$1,'FC inventory'!$B$2:$B999,"BCT",'FC inventory'!$C$2:$C999,"In") -> 0 | E4: =sumifs('FC inventory'!G2:G999,'FC inventory'!$A$2:$A999,$A$1,'FC inventory'!$B$2:$B999,"BCT",'FC inventory'!$C$2:$C999,"In") -> 0 | F4: =sumifs('FC inventory'!H2:H999,'FC inventory'!$A$2:$A999,$A$1,'FC inventory'!$B$2:$B999,"BCT",'FC inventory'!$C$2:$C999,"In") -> 0 | G4: =sumifs('FC inventory'!I2:I999,'FC inventory'!$A$2:$A999,$A$1,'FC inventory'!$B$2:$B999,"BCT",'FC inventory'!$C$2:$C999,"In") -> 0 | H4: =sumifs('FC inventory'!J2:J999,'FC inventory'!$A$2:$A999,$A$1,'FC inventory'!$B$2:$B999,"BCT",'FC inventory'!$C$2:$C999,"In") -> 0 | I4: =sumifs('FC inventory'!K2:K999,'FC inventory'!$A$2:$A999,$A$1,'FC inventory'!$B$2:$B999,"BCT",'FC inventory'!$C$2:$C999,"In") -> 0 | ... AF4: =sumifs('FC inventory'!AH2:AH999,'FC inventory'!$A$2:$A999,$A$1,'FC inventory'!$B$2:$B999,"BCT",'FC inventory'!$C$2:$C999,"In") -> 0
A5: Out | B5: =sumifs('FC inventory'!D2:D999,'FC inventory'!$A$2:$A999,$A$1,'FC inventory'!$B$2:$B999,"BCT",'FC inventory'!$C$2:$C999,"Out") -> 0 | C5: =sumifs('FC inventory'!E2:E999,'FC inventory'!$A$2:$A999,$A$1,'FC inventory'!$B$2:$B999,"BCT",'FC inventory'!$C$2:$C999,"Out") -> 0 | D5: =sumifs('FC inventory'!F2:F999,'FC inventory'!$A$2:$A999,$A$1,'FC inventory'!$B$2:$B999,"BCT",'FC inventory'!$C$2:$C999,"Out") -> 0 | E5: =sumifs('FC inventory'!G2:G999,'FC inventory'!$A$2:$A999,$A$1,'FC inventory'!$B$2:$B999,"BCT",'FC inventory'!$C$2:$C999,"Out") -> 0 | F5: =sumifs('FC inventory'!H2:H999,'FC inventory'!$A$2:$A999,$A$1,'FC inventory'!$B$2:$B999,"BCT",'FC inventory'!$C$2:$C999,"Out") -> 0 | G5: =sumifs('FC inventory'!I2:I999,'FC inventory'!$A$2:$A999,$A$1,'FC inventory'!$B$2:$B999,"BCT",'FC inventory'!$C$2:$C999,"Out") -> 0 | H5: =sumifs('FC inventory'!J2:J999,'FC inventory'!$A$2:$A999,$A$1,'FC inventory'!$B$2:$B999,"BCT",'FC inventory'!$C$2:$C999,"Out") -> 0 | I5: =sumifs('FC inventory'!K2:K999,'FC inventory'!$A$2:$A999,$A$1,'FC inventory'!$B$2:$B999,"BCT",'FC inventory'!$C$2:$C999,"Out") -> 0 | ... AF5: =sumifs('FC inventory'!AH2:AH999,'FC inventory'!$A$2:$A999,$A$1,'FC inventory'!$B$2:$B999,"BCT",'FC inventory'!$C$2:$C999,"Out") -> 0
A6: Returned | B6: =SUMIFS('FC inventory'!D2:D999,'FC inventory'!$A$2:$A999,$A$1,'FC inventory'!$B$2:$B999,"BCT",'FC inventory'!$C$2:$C999,"Returned") -> 0 | C6: =SUMIFS('FC inventory'!E2:E999,'FC inventory'!$A$2:$A999,$A$1,'FC inventory'!$B$2:$B999,"BCT",'FC inventory'!$C$2:$C999,"Returned") -> 0 | D6: =SUMIFS('FC inventory'!F2:F999,'FC inventory'!$A$2:$A999,$A$1,'FC inventory'!$B$2:$B999,"BCT",'FC inventory'!$C$2:$C999,"Returned") -> 0 | E6: =SUMIFS('FC inventory'!G2:G999,'FC inventory'!$A$2:$A999,$A$1,'FC inventory'!$B$2:$B999,"BCT",'FC inventory'!$C$2:$C999,"Returned") -> 0 | F6: =SUMIFS('FC inventory'!H2:H999,'FC inventory'!$A$2:$A999,$A$1,'FC inventory'!$B$2:$B999,"BCT",'FC inventory'!$C$2:$C999,"Returned") -> 0 | G6: =SUMIFS('FC inventory'!I2:I999,'FC inventory'!$A$2:$A999,$A$1,'FC inventory'!$B$2:$B999,"BCT",'FC inventory'!$C$2:$C999,"Returned") -> 0 | H6: =SUMIFS('FC inventory'!J2:J999,'FC inventory'!$A$2:$A999,$A$1,'FC inventory'!$B$2:$B999,"BCT",'FC inventory'!$C$2:$C999,"Returned") -> 0 | I6: =SUMIFS('FC inventory'!K2:K999,'FC inventory'!$A$2:$A999,$A$1,'FC inventory'!$B$2:$B999,"BCT",'FC inventory'!$C$2:$C999,"Returned") -> 0 | ... AF6: =SUMIFS('FC inventory'!AH2:AH999,'FC inventory'!$A$2:$A999,$A$1,'FC inventory'!$B$2:$B999,"BCT",'FC inventory'!$C$2:$C999,"Returned") -> 0
A7: Balance | B7: =B3+B4-B5+B6 -> -2 | C7: =C3+C4-C5+C6 -> 0 | D7: =D3+D4-D5+D6 -> 0 | E7: =E3+E4-E5+E6 -> -1 | F7: =F3+F4-F5+F6 -> 0 | G7: =G3+G4-G5+G6 -> 35 | H7: =H3+H4-H5+H6 -> 0 | I7: =I3+I4-I5+I6 -> 0 | ... AF7: =AF3+AF4-AF5+AF6 -> 0

Sheet Eleyele
A1: =TODAY() -> 45889 | B1: Agemawo 1kg | C1: Boneless Beef 1kg | D1: Cow Hump 1kg | E1: Cow Head & Neck 1kg | F1: Goat Meat 1kg | G1: Chicken 1kg | H1: Titus 1kg (uncleaned) | I1: Titus 1kg (Cleaned) | J1: Hake 1kg (Cleaned) | K1: Hake 1kg (Uncleaned) | L1: Value Pack (Cow Tongue) | M1: Value Pack (Cow Assorted) | N1: Token Pack (Cow Minced Meat) | O1: Token Pack (Agemawo) | P1: Token pack(boneless beef) | Q1: Token Pack (Cow Tail) | R1: Token Pack (Cow Head & Neck) | S1: Token Pack (Cow Hump) | T1: Token Pack (Goat Meat) | U1: Token Pack (Chicken) | V1: Token Pack (Chicken Gizzard) | W1: Token Pack (Pomo) | X1: Token Pack (Shaki & Roundabout) | Y1: Token Pack (Cow Assorted) | Z1: Token Pack (Cow Leg) | AA1: Token Pack (Goat Assorted) | AB1: Token Pack (Titus) | AC1: Token Pack (Hake) | AD1: Token (small snail) | AE1: Token (big snail) | AF1: Token (Goat head & leg)
A2: Stock Count | B2: 0 | C2: 0 | D2: 0 | E2: 0 | F2: 0 | G2: 0 | H2: 0 | I2: 0 | J2: 0 | K2: 0 | L2: 0 | M2: 0 | N2: 0 | O2: 0 | P2: 0 | Q2: 0 | R2: 0 | S2: 0 | T2: 0 | U2: 0 | V2: 0 | W2: 0 | X2: 0 | Y2: 0 | Z2: 0 | AA2: 0 | AB2: 0 | AC2: 0 | AD2: 0 | AE2: 0 | AF2: 0
A3: Opening Stock | B3: =sumifs('FC inventory'!D2:D999,'FC inventory'!$A$2:$A999,"<"&$A$1,'FC inventory'!$B$2:$B999,"Eleyele",'FC inventory'!$C$2:$C999,"In")-sumifs('FC inventory'!D2:D999,'FC inventory'!$A$2:$A999,"<"&$A$1,'FC inventory'!$B$2:$B999,"Eleyele",'FC inventory'!$C$2:$C999,"Out")+SUMIFS('FC inventory'!D2:D999,'FC inventory'!$A$2:$A999,"<"&$A$1,'FC inventory'!$B$2:$B999,"Eleyele",'FC inventory'!$C$2:$C999,"Returned") -> 0 | C3: =sumifs('FC inventory'!E2:E999,'FC inventory'!$A$2:$A999,"<"&$A$1,'FC inventory'!$B$2:$B999,"Eleyele",'FC inventory'!$C$2:$C999,"In")-sumifs('FC inventory'!E2:E999,'FC inventory'!$A$2:$A999,"<"&$A$1,'FC inventory'!$B$2:$B999,"Eleyele",'FC inventory'!$C$2:$C999,"Out")+SUMIFS('FC inventory'!E2:E999,'FC inventory'!$A$2:$A999,"<"&$A$1,'FC inventory'!$B$2:$B999,"Eleyele",'FC inventory'!$C$2:$C999,"Returned") -> 0 | D3: =sumifs('FC inventory'!F2:F999,'FC inventory'!$A$2:$A999,"<"&$A$1,'FC inventory'!$B$2:$B999,"Eleyele",'FC inventory'!$C$2:$C999,"In")-sumifs('FC inventory'!F2:F999,'FC inventory'!$A$2:$A999,"<"&$A$1,'FC inventory'!$B$2:$B999,"Eleyele",'FC inventory'!$C$2:$C999,"Out")+SUMIFS('FC inventory'!F2:F999,'FC inventory'!$A$2:$A999,"<"&$A$1,'FC inventory'!$B$2:$B999,"Eleyele",'FC inventory'!$C$2:$C999,"Returned") -> 0 | E3: =sumifs('FC inventory'!G2:G999,'FC inventory'!$A$2:$A999,"<"&$A$1,'FC inventory'!$B$2:$B999,"Eleyele",'FC inventory'!$C$2:$C999,"In")-sumifs('FC inventory'!G2:G999,'FC inventory'!$A$2:$A999,"<"&$A$1,'FC inventory'!$B$2:$B999,"Eleyele",'FC inventory'!$C$2:$C999,"Out")+SUMIFS('FC inventory'!G2:G999,'FC inventory'!$A$2:$A999,"<"&$A$1,'FC inventory'!$B$2:$B999,"Eleyele",'FC inventory'!$C$2:$C999,"Returned") -> 0 | F3: =sumifs('FC inventory'!H2:H999,'FC inventory'!$A$2:$A999,"<"&$A$1,'FC inventory'!$B$2:$B999,"Eleyele",'FC inventory'!$C$2:$C999,"In")-sumifs('FC inventory'!H2:H999,'FC inventory'!$A$2:$A999,"<"&$A$1,'FC inventory'!$B$2:$B999,"Eleyele",'FC inventory'!$C$2:$C999,"Out")+SUMIFS('FC inventory'!H2:H999,'FC inventory'!$A$2:$A999,"<"&$A$1,'FC inventory'!$B$2:$B999,"Eleyele",'FC inventory'!$C$2:$C999,"Returned") -> 0 | G3: =sumifs('FC inventory'!I2:I999,'FC inventory'!$A$2:$A999,"<"&$A$1,'FC inventory'!$B$2:$B999,"Eleyele",'FC inventory'!$C$2:$C999,"In")-sumifs('FC inventory'!I2:I999,'FC inventory'!$A$2:$A999,"<"&$A$1,'FC inventory'!$B$2:$B999,"Eleyele",'FC inventory'!$C$2:$C999,"Out")+SUMIFS('FC inventory'!I2:I999,'FC inventory'!$A$2:$A999,"<"&$A$1,'FC inventory'!$B$2:$B999,"Eleyele",'FC inventory'!$C$2:$C999,"Returned") -> 0 | H3: =sumifs('FC inventory'!J2:J999,'FC inventory'!$A$2:$A999,"<"&$A$1,'FC inventory'!$B$2:$B999,"Eleyele",'FC inventory'!$C$2:$C999,"In")-sumifs('FC inventory'!J2:J999,'FC inventory'!$A$2:$A999,"<"&$A$1,'FC inventory'!$B$2:$B999,"Eleyele",'FC inventory'!$C$2:$C999,"Out")+SUMIFS('FC inventory'!J2:J999,'FC inventory'!$A$2:$A999,"<"&$A$1,'FC inventory'!$B$2:$B999,"Eleyele",'FC inventory'!$C$2:$C999,"Returned") -> 0 | I3: =sumifs('FC inventory'!K2:K999,'FC inventory'!$A$2:$A999,"<"&$A$1,'FC inventory'!$B$2:$B999,"Eleyele",'FC inventory'!$C$2:$C999,"In")-sumifs('FC inventory'!K2:K999,'FC inventory'!$A$2:$A999,"<"&$A$1,'FC inventory'!$B$2:$B999,"Eleyele",'FC inventory'!$C$2:$C999,"Out")+SUMIFS('FC inventory'!K2:K999,'FC inventory'!$A$2:$A999,"<"&$A$1,'FC inventory'!$B$2:$B999,"Eleyele",'FC inventory'!$C$2:$C999,"Returned") -> 0 | ... AF3: =sumifs('FC inventory'!AH2:AH999,'FC inventory'!$A$2:$A999,"<"&$A$1,'FC inventory'!$B$2:$B999,"Eleyele",'FC inventory'!$C$2:$C999,"In")-sumifs('FC inventory'!AH2:AH999,'FC inventory'!$A$2:$A999,"<"&$A$1,'FC inventory'!$B$2:$B999,"Eleyele",'FC inventory'!$C$2:$C999,"Out")+SUMIFS('FC inventory'!AH2:AH999,'FC inventory'!$A$2:$A999,"<"&$A$1,'FC inventory'!$B$2:$B999,"Eleyele",'FC inventory'!$C$2:$C999,"Returned") -> 0
A4: In | B4: =sumifs('FC inventory'!D2:D999,'FC inventory'!$A$2:$A999,$A$1,'FC inventory'!$B$2:$B999,"Eleyele",'FC inventory'!$C$2:$C999,"In") -> 0 | C4: =sumifs('FC inventory'!E2:E999,'FC inventory'!$A$2:$A999,$A$1,'FC inventory'!$B$2:$B999,"Eleyele",'FC inventory'!$C$2:$C999,"In") -> 0 | D4: =sumifs('FC inventory'!F2:F999,'FC inventory'!$A$2:$A999,$A$1,'FC inventory'!$B$2:$B999,"Eleyele",'FC inventory'!$C$2:$C999,"In") -> 0 | E4: =sumifs('FC inventory'!G2:G999,'FC inventory'!$A$2:$A999,$A$1,'FC inventory'!$B$2:$B999,"Eleyele",'FC inventory'!$C$2:$C999,"In") -> 0 | F4: =sumifs('FC inventory'!H2:H999,'FC inventory'!$A$2:$A999,$A$1,'FC inventory'!$B$2:$B999,"Eleyele",'FC inventory'!$C$2:$C999,"In") -> 0 | G4: =sumifs('FC inventory'!I2:I999,'FC inventory'!$A$2:$A999,$A$1,'FC inventory'!$B$2:$B999,"Eleyele",'FC inventory'!$C$2:$C999,"In") -> 0 | H4: =sumifs('FC inventory'!J2:J999,'FC inventory'!$A$2:$A999,$A$1,'FC inventory'!$B$2:$B999,"Eleyele",'FC inventory'!$C$2:$C999,"In") -> 0 | I4: =sumifs('FC inventory'!K2:K999,'FC inventory'!$A$2:$A999,$A$1,'FC inventory'!$B$2:$B999,"Eleyele",'FC inventory'!$C$2:$C999,"In") -> 0 | ... AF4: =sumifs('FC inventory'!AH2:AH999,'FC inventory'!$A$2:$A999,$A$1,'FC inventory'!$B$2:$B999,"Eleyele",'FC inventory'!$C$2:$C999,"In") -> 0
A5: Out | B5: =sumifs('FC inventory'!D2:D999,'FC inventory'!$A$2:$A999,$A$1,'FC inventory'!$B$2:$B999,"Eleyele",'FC inventory'!$C$2:$C999,"Out") -> 0 | C5: =sumifs('FC inventory'!E2:E999,'FC inventory'!$A$2:$A999,$A$1,'FC inventory'!$B$2:$B999,"Eleyele",'FC inventory'!$C$2:$C999,"Out") -> 0 | D5: =sumifs('FC inventory'!F2:F999,'FC inventory'!$A$2:$A999,$A$1,'FC inventory'!$B$2:$B999,"Eleyele",'FC inventory'!$C$2:$C999,"Out") -> 0 | E5: =sumifs('FC inventory'!G2:G999,'FC inventory'!$A$2:$A999,$A$1,'FC inventory'!$B$2:$B999,"Eleyele",'FC inventory'!$C$2:$C999,"Out") -> 0 | F5: =sumifs('FC inventory'!H2:H999,'FC inventory'!$A$2:$A999,$A$1,'FC inventory'!$B$2:$B999,"Eleyele",'FC inventory'!$C$2:$C999,"Out") -> 0 | G5: =sumifs('FC inventory'!I2:I999,'FC inventory'!$A$2:$A999,$A$1,'FC inventory'!$B$2:$B999,"Eleyele",'FC inventory'!$C$2:$C999,"Out") -> 0 | H5: =sumifs('FC inventory'!J2:J999,'FC inventory'!$A$2:$A999,$A$1,'FC inventory'!$B$2:$B999,"Eleyele",'FC inventory'!$C$2:$C999,"Out") -> 0 | I5: =sumifs('FC inventory'!K2:K999,'FC inventory'!$A$2:$A999,$A$1,'FC inventory'!$B$2:$B999,"Eleyele",'FC inventory'!$C$2:$C999,"Out") -> 0 | ... AF5: =sumifs('FC inventory'!AH2:AH999,'FC inventory'!$A$2:$A999,$A$1,'FC inventory'!$B$2:$B999,"Eleyele",'FC inventory'!$C$2:$C999,"Out") -> 0
A6: Returned | B6: =SUMIFS('FC inventory'!D2:D999,'FC inventory'!$A$2:$A999,$A$1,'FC inventory'!$B$2:$B999,"Eleyele",'FC inventory'!$C$2:$C999,"Returned") -> 0 | C6: =SUMIFS('FC inventory'!E2:E999,'FC inventory'!$A$2:$A999,$A$1,'FC inventory'!$B$2:$B999,"Eleyele",'FC inventory'!$C$2:$C999,"Returned") -> 0 | D6: =SUMIFS('FC inventory'!F2:F999,'FC inventory'!$A$2:$A999,$A$1,'FC inventory'!$B$2:$B999,"Eleyele",'FC inventory'!$C$2:$C999,"Returned") -> 0 | E6: =SUMIFS('FC inventory'!G2:G999,'FC inventory'!$A$2:$A999,$A$1,'FC inventory'!$B$2:$B999,"Eleyele",'FC inventory'!$C$2:$C999,"Returned") -> 0 | F6: =SUMIFS('FC inventory'!H2:H999,'FC inventory'!$A$2:$A999,$A$1,'FC inventory'!$B$2:$B999,"Eleyele",'FC inventory'!$C$2:$C999,"Returned") -> 0 | G6: =SUMIFS('FC inventory'!I2:I999,'FC inventory'!$A$2:$A999,$A$1,'FC inventory'!$B$2:$B999,"Eleyele",'FC inventory'!$C$2:$C999,"Returned") -> 0 | H6: =SUMIFS('FC inventory'!J2:J999,'FC inventory'!$A$2:$A999,$A$1,'FC inventory'!$B$2:$B999,"Eleyele",'FC inventory'!$C$2:$C999,"Returned") -> 0 | I6: =SUMIFS('FC inventory'!K2:K999,'FC inventory'!$A$2:$A999,$A$1,'FC inventory'!$B$2:$B999,"Eleyele",'FC inventory'!$C$2:$C999,"Returned") -> 0 | ... AF6: =SUMIFS('FC inventory'!AH2:AH999,'FC inventory'!$A$2:$A999,$A$1,'FC inventory'!$B$2:$B999,"Eleyele",'FC inventory'!$C$2:$C999,"Returned") -> 0
A7: Balance | B7: =B3+B4-B5+B6 -> 0 | C7: =C3+C4-C5+C6 -> 0 | D7: =D3+D4-D5+D6 -> 0 | E7: =E3+E4-E5+E6 -> 0 | F7: =F3+F4-F5+F6 -> 0 | G7: =G3+G4-G5+G6 -> 0 | H7: =H3+H4-H5+H6 -> 0 | I7: =I3+I4-I5+I6 -> 0 | ... AF7: =AF3+AF4-AF5+AF6 -> 0

Sheet Felele
A1: =TODAY() -> 45889 | B1: Agemawo 1kg | C1: Boneless Beef 1kg | D1: Cow Hump 1kg | E1: Cow Head & Neck 1kg | F1: Goat Meat 1kg | G1: Chicken 1kg | H1: Titus 1kg (uncleaned) | I1: Titus 1kg (Cleaned) | J1: Hake 1kg (Cleaned) | K1: Hake 1kg (Uncleaned) | L1: Value Pack (Cow Tongue) | M1: Value Pack (Cow Assorted) | N1: Token Pack (Cow Minced Meat) | O1: Token Pack (Agemawo) | P1: Token pack(boneless beef) | Q1: Token Pack (Cow Tail) | R1: Token Pack (Cow Head & Neck) | S1: Token Pack (Cow Hump) | T1: Token Pack (Goat Meat) | U1: Token Pack (Chicken) | V1: Token Pack (Chicken Gizzard) | W1: Token Pack (Pomo) | X1: Token Pack (Shaki & Roundabout) | Y1: Token Pack (Cow Assorted) | Z1: Token Pack (Cow Leg) | AA1: Token Pack (Goat Assorted) | AB1: Token Pack (Titus) | AC1: Token Pack (Hake) | AD1: Token (small snail) | AE1: Token (big snail) | AF1: Token (Goat head & leg)
A2: Stock Count | B2: 0 | C2: 0 | D2: 0 | E2: 0 | F2: 0 | G2: 0 | H2: 0 | I2: 0 | J2: 0 | K2: 0 | L2: 0 | M2: 0 | N2: 0 | O2: 0 | P2: 0 | Q2: 0 | R2: 0 | S2: 0 | T2: 0 | U2: 0 | V2: 0 | W2: 0 | X2: 0 | Y2: 0 | Z2: 0 | AA2: 0 | AB2: 0 | AC2: 0 | AD2: 0 | AE2: 0 | AF2: 0
A3: Opening Stock | B3: =sumifs('FC inventory'!D2:D999,'FC inventory'!$A$2:$A999,"<"&$A$1,'FC inventory'!$B$2:$B999,"Felele",'FC inventory'!$C$2:$C999,"In")-sumifs('FC inventory'!D2:D999,'FC inventory'!$A$2:$A999,"<"&$A$1,'FC inventory'!$B$2:$B999,"Felele",'FC inventory'!$C$2:$C999,"Out")+SUMIFS('FC inventory'!D2:D999,'FC inventory'!$A$2:$A999,"<"&$A$1,'FC inventory'!$B$2:$B999,"Felele",'FC inventory'!$C$2:$C999,"Returned") -> 0 | C3: =sumifs('FC inventory'!E2:E999,'FC inventory'!$A$2:$A999,"<"&$A$1,'FC inventory'!$B$2:$B999,"Felele",'FC inventory'!$C$2:$C999,"In")-sumifs('FC inventory'!E2:E999,'FC inventory'!$A$2:$A999,"<"&$A$1,'FC inventory'!$B$2:$B999,"Felele",'FC inventory'!$C$2:$C999,"Out")+SUMIFS('FC inventory'!E2:E999,'FC inventory'!$A$2:$A999,"<"&$A$1,'FC inventory'!$B$2:$B999,"Felele",'FC inventory'!$C$2:$C999,"Returned") -> 0 | D3: =sumifs('FC inventory'!F2:F999,'FC inventory'!$A$2:$A999,"<"&$A$1,'FC inventory'!$B$2:$B999,"Felele",'FC inventory'!$C$2:$C999,"In")-sumifs('FC inventory'!F2:F999,'FC inventory'!$A$2:$A999,"<"&$A$1,'FC inventory'!$B$2:$B999,"Felele",'FC inventory'!$C$2:$C999,"Out")+SUMIFS('FC inventory'!F2:F999,'FC inventory'!$A$2:$A999,"<"&$A$1,'FC inventory'!$B$2:$B999,"Felele",'FC inventory'!$C$2:$C999,"Returned") -> 0 | E3: =sumifs('FC inventory'!G2:G999,'FC inventory'!$A$2:$A999,"<"&$A$1,'FC inventory'!$B$2:$B999,"Felele",'FC inventory'!$C$2:$C999,"In")-sumifs('FC inventory'!G2:G999,'FC inventory'!$A$2:$A999,"<"&$A$1,'FC inventory'!$B$2:$B999,"Felele",'FC inventory'!$C$2:$C999,"Out")+SUMIFS('FC inventory'!G2:G999,'FC inventory'!$A$2:$A999,"<"&$A$1,'FC inventory'!$B$2:$B999,"Felele",'FC inventory'!$C$2:$C999,"Returned") -> 0 | F3: =sumifs('FC inventory'!H2:H999,'FC inventory'!$A$2:$A999,"<"&$A$1,'FC inventory'!$B$2:$B999,"Felele",'FC inventory'!$C$2:$C999,"In")-sumifs('FC inventory'!H2:H999,'FC inventory'!$A$2:$A999,"<"&$A$1,'FC inventory'!$B$2:$B999,"Felele",'FC inventory'!$C$2:$C999,"Out")+SUMIFS('FC inventory'!H2:H999,'FC inventory'!$A$2:$A999,"<"&$A$1,'FC inventory'!$B$2:$B999,"Felele",'FC inventory'!$C$2:$C999,"Returned") -> 0 | G3: =sumifs('FC inventory'!I2:I999,'FC inventory'!$A$2:$A999,"<"&$A$1,'FC inventory'!$B$2:$B999,"Felele",'FC inventory'!$C$2:$C999,"In")-sumifs('FC inventory'!I2:I999,'FC inventory'!$A$2:$A999,"<"&$A$1,'FC inventory'!$B$2:$B999,"Felele",'FC inventory'!$C$2:$C999,"Out")+SUMIFS('FC inventory'!I2:I999,'FC inventory'!$A$2:$A999,"<"&$A$1,'FC inventory'!$B$2:$B999,"Felele",'FC inventory'!$C$2:$C999,"Returned") -> 26 | H3: =sumifs('FC inventory'!J2:J999,'FC inventory'!$A$2:$A999,"<"&$A$1,'FC inventory'!$B$2:$B999,"Felele",'FC inventory'!$C$2:$C999,"In")-sumifs('FC inventory'!J2:J999,'FC inventory'!$A$2:$A999,"<"&$A$1,'FC inventory'!$B$2:$B999,"Felele",'FC inventory'!$C$2:$C999,"Out")+SUMIFS('FC inventory'!J2:J999,'FC inventory'!$A$2:$A999,"<"&$A$1,'FC inventory'!$B$2:$B999,"Felele",'FC inventory'!$C$2:$C999,"Returned") -> 0 | I3: =sumifs('FC inventory'!K2:K999,'FC inventory'!$A$2:$A999,"<"&$A$1,'FC inventory'!$B$2:$B999,"Felele",'FC inventory'!$C$2:$C999,"In")-sumifs('FC inventory'!K2:K999,'FC inventory'!$A$2:$A999,"<"&$A$1,'FC inventory'!$B$2:$B999,"Felele",'FC inventory'!$C$2:$C999,"Out")+SUMIFS('FC inventory'!K2:K999,'FC inventory'!$A$2:$A999,"<"&$A$1,'FC inventory'!$B$2:$B999,"Felele",'FC inventory'!$C$2:$C999,"Returned") -> 0 | ... AF3: =sumifs('FC inventory'!AH2:AH999,'FC inventory'!$A$2:$A999,"<"&$A$1,'FC inventory'!$B$2:$B999,"Felele",'FC inventory'!$C$2:$C999,"In")-sumifs('FC inventory'!AH2:AH999,'FC inventory'!$A$2:$A999,"<"&$A$1,'FC inventory'!$B$2:$B999,"Felele",'FC inventory'!$C$2:$C999,"Out")+SUMIFS('FC inventory'!AH2:AH999,'FC inventory'!$A$2:$A999,"<"&$A$1,'FC inventory'!$B$2:$B999,"Felele",'FC inventory'!$C$2:$C999,"Returned") -> 0
A4: In | B4: =sumifs('FC inventory'!D2:D999,'FC inventory'!$A$2:$A999,$A$1,'FC inventory'!$B$2:$B999,"Felele",'FC inventory'!$C$2:$C999,"In") -> 0 | C4: =sumifs('FC inventory'!E2:E999,'FC inventory'!$A$2:$A999,$A$1,'FC inventory'!$B$2:$B999,"Felele",'FC inventory'!$C$2:$C999,"In") -> 0 | D4: =sumifs('FC inventory'!F2:F999,'FC inventory'!$A$2:$A999,$A$1,'FC inventory'!$B$2:$B999,"Felele",'FC inventory'!$C$2:$C999,"In") -> 0 | E4: =sumifs('FC inventory'!G2:G999,'FC inventory'!$A$2:$A999,$A$1,'FC inventory'!$B$2:$B999,"Felele",'FC inventory'!$C$2:$C999,"In") -> 0 | F4: =sumifs('FC inventory'!H2:H999,'FC inventory'!$A$2:$A999,$A$1,'FC inventory'!$B$2:$B999,"Felele",'FC inventory'!$C$2:$C999,"In") -> 0 | G4: =sumifs('FC inventory'!I2:I999,'FC inventory'!$A$2:$A999,$A$1,'FC inventory'!$B$2:$B999,"Felele",'FC inventory'!$C$2:$C999,"In") -> 0 | H4: =sumifs('FC inventory'!J2:J999,'FC inventory'!$A$2:$A999,$A$1,'FC inventory'!$B$2:$B999,"Felele",'FC inventory'!$C$2:$C999,"In") -> 0 | I4: =sumifs('FC inventory'!K2:K999,'FC inventory'!$A$2:$A999,$A$1,'FC inventory'!$B$2:$B999,"Felele",'FC inventory'!$C$2:$C999,"In") -> 0 | ... AF4: =sumifs('FC inventory'!AH2:AH999,'FC inventory'!$A$2:$A999,$A$1,'FC inventory'!$B$2:$B999,"Felele",'FC inventory'!$C$2:$C999,"In") -> 0
A5: Out | B5: =sumifs('FC inventory'!D2:D999,'FC inventory'!$A$2:$A999,$A$1,'FC inventory'!$B$2:$B999,"Felele",'FC inventory'!$C$2:$C999,"Out") -> 0 | C5: =sumifs('FC inventory'!E2:E999,'FC inventory'!$A$2:$A999,$A$1,'FC inventory'!$B$2:$B999,"Felele",'FC inventory'!$C$2:$C999,"Out") -> 0 | D5: =sumifs('FC inventory'!F2:F999,'FC inventory'!$A$2:$A999,$A$1,'FC inventory'!$B$2:$B999,"Felele",'FC inventory'!$C$2:$C999,"Out") -> 0 | E5: =sumifs('FC inventory'!G2:G999,'FC inventory'!$A$2:$A999,$A$1,'FC inventory'!$B$2:$B999,"Felele",'FC inventory'!$C$2:$C999,"Out") -> 0 | F5: =sumifs('FC inventory'!H2:H999,'FC inventory'!$A$2:$A999,$A$1,'FC inventory'!$B$2:$B999,"Felele",'FC inventory'!$C$2:$C999,"Out") -> 0 | G5: =sumifs('FC inventory'!I2:I999,'FC inventory'!$A$2:$A999,$A$1,'FC inventory'!$B$2:$B999,"Felele",'FC inventory'!$C$2:$C999,"Out") -> 0 | H5: =sumifs('FC inventory'!J2:J999,'FC inventory'!$A$2:$A999,$A$1,'FC inventory'!$B$2:$B999,"Felele",'FC inventory'!$C$2:$C999,"Out") -> 0 | I5: =sumifs('FC inventory'!K2:K999,'FC inventory'!$A$2:$A999,$A$1,'FC inventory'!$B$2:$B999,"Felele",'FC inventory'!$C$2:$C999,"Out") -> 0 | ... AF5: =sumifs('FC inventory'!AH2:AH999,'FC inventory'!$A$2:$A999,$A$1,'FC inventory'!$B$2:$B999,"Felele",'FC inventory'!$C$2:$C999,"Out") -> 0
A6: Returned | B6: =SUMIFS('FC inventory'!D2:D999,'FC inventory'!$A$2:$A999,$A$1,'FC inventory'!$B$2:$B999,"Felele",'FC inventory'!$C$2:$C999,"Returned") -> 0 | C6: =SUMIFS('FC inventory'!E2:E999,'FC inventory'!$A$2:$A999,$A$1,'FC inventory'!$B$2:$B999,"Felele",'FC inventory'!$C$2:$C999,"Returned") -> 0 | D6: =SUMIFS('FC inventory'!F2:F999,'FC inventory'!$A$2:$A999,$A$1,'FC inventory'!$B$2:$B999,"Felele",'FC inventory'!$C$2:$C999,"Returned") -> 0 | E6: =SUMIFS('FC inventory'!G2:G999,'FC inventory'!$A$2:$A999,$A$1,'FC inventory'!$B$2:$B999,"Felele",'FC inventory'!$C$2:$C999,"Returned") -> 0 | F6: =SUMIFS('FC inventory'!H2:H999,'FC inventory'!$A$2:$A999,$A$1,'FC inventory'!$B$2:$B999,"Felele",'FC inventory'!$C$2:$C999,"Returned") -> 0 | G6: =SUMIFS('FC inventory'!I2:I999,'FC inventory'!$A$2:$A999,$A$1,'FC inventory'!$B$2:$B999,"Felele",'FC inventory'!$C$2:$C999,"Returned") -> 0 | H6: =SUMIFS('FC inventory'!J2:J999,'FC inventory'!$A$2:$A999,$A$1,'FC inventory'!$B$2:$B999,"Felele",'FC inventory'!$C$2:$C999,"Returned") -> 0 | I6: =SUMIFS('FC inventory'!K2:K999,'FC inventory'!$A$2:$A999,$A$1,'FC inventory'!$B$2:$B999,"Felele",'FC inventory'!$C$2:$C999,"Returned") -> 0 | ... AF6: =SUMIFS('FC inventory'!AH2:AH999,'FC inventory'!$A$2:$A999,$A$1,'FC inventory'!$B$2:$B999,"Felele",'FC inventory'!$C$2:$C999,"Returned") -> 0
A7: Balance | B7: =B3+B4-B5+B6 -> 0 | C7: =C3+C4-C5+C6 -> 0 | D7: =D3+D4-D5+D6 -> 0 | E7: =E3+E4-E5+E6 -> 0 | F7: =F3+F4-F5+F6 -> 0 | G7: =G3+G4-G5+G6 -> 26 | H7: =H3+H4-H5+H6 -> 0 | I7: =I3+I4-I5+I6 -> 0 | ... AF7: =AF3+AF4-AF5+AF6 -> 0

Sheet Closing stock
A1: Name of fulfillment centre | B1: Agemawo 1kg | C1: Boneless Beef 1kg | D1: Cow Hump 1kg | E1: Cow Head & Neck 1kg | F1: Goat Meat 1kg | G1: Chicken 1kg | H1: Titus 1kg (uncleaned) | I1: Titus 1kg (Cleaned) | J1: Hake 1kg (Cleaned) | K1: Hake 1kg (Uncleaned) | L1: Value Pack (Cow Tongue) | M1: Value Pack (Cow Assorted) | N1: Token Pack (Cow Minced Meat) | O1: Token Pack (Agemawo) | P1: Token pack(boneless beef) | Q1: Token Pack (Cow Tail) | R1: Token Pack (Cow Head & Neck) | S1: Token Pack (Cow Hump) | T1: Token Pack (Goat Meat) | U1: Token Pack (Chicken) | V1: Token Pack (Chicken Gizzard) | W1: Token Pack (Pomo) | X1: Token Pack (Shaki & Roundabout) | Y1: Token Pack (Cow Assorted) | Z1: Token Pack (Cow Leg) | AA1: Token Pack (Goat Assorted) | AB1: Token Pack (Titus) | AC1: Token Pack (Hake) | AD1: Token (small snail) | AE1: Token (big snail) | AF1: Token (Goat head & leg)
